<?xml version="1.0" encoding="utf-8"?>
<!-- This URDF was automatically created by SolidWorks to URDF Exporter! Originally created by Stephen Brawner (brawner@gmail.com) 
     Commit Version: 1.6.0-4-g7f85cfe  Build Version: 1.6.7995.38578
     For more information, please see http://wiki.ros.org/sw_urdf_exporter -->
<robot
  name="igus_description">

  <link name="world"/>

  <joint name="base_joint" type="fixed">
    <parent link="world"/>
    <child link="base_link"/>
    <origin rpy="0 0 0" xyz="0.0 0.0 0.0"/>
  </joint>

  <link
    name="base_link">
    <inertial>
      <origin
        xyz="0.00060987 -0.0041281 0.28783"
        rpy="0 0 0" />
      <!--<mass
        value="3.8503" />-->
        <mass
        value="10" />
      <inertia
        ixx="0.41874"
        ixy="8.8766E-05"
        ixz="-6.9146E-06"
        iyy="0.41533"
        iyz="0.0042277"
        izz="0.038257" />
    </inertial>
    <visual>
      <origin
        xyz="0 0 0"
        rpy="0 0 0" />
      <geometry>
        <mesh
          filename="package://igus_description/meshes/base_link.STL" />
      </geometry>
      <material
        name="">
        <color
          rgba="0.79216 0.81961 0.93333 1" />
      </material>
    </visual>
    <collision>
      <origin
        xyz="0 0 0"
        rpy="0 0 0" />
      <geometry>
        <mesh
          filename="package://igus_description/meshes/base_link.STL" />
      </geometry>
    </collision>
  </link>
  <link
    name="prism_link">
    <inertial>
      <origin
        xyz="0.098545 1.5436E-08 0.029147"
        rpy="0 0 0" />
      <mass
        value="0.82467" />
      <inertia
        ixx="0.0024655"
        ixy="-3.8705E-10"
        ixz="-0.00050705"
        iyy="0.0033628"
        iyz="1.2294E-10"
        izz="0.0025901" />
    </inertial>
    <visual>
      <origin
        xyz="0 0 0"
        rpy="0 0 0" />
      <geometry>
        <mesh
          filename="package://igus_description/meshes/prism_link.STL" />
      </geometry>
      <material
        name="">
        <color
          rgba="0.79216 0.81961 0.93333 1" />
      </material>
    </visual>
    <collision>
      <origin
        xyz="0 0 0"
        rpy="0 0 0" />
      <geometry>
        <mesh
          filename="package://igus_description/meshes/prism_link.STL" />
      </geometry>
    </collision>
  </link>
  <joint
    name="prism_joint"
    type="prismatic">
    <origin
      xyz="0 0 0.74133"
      rpy="0 0 1.5708" />
    <parent
      link="base_link" />
    <child
      link="prism_link" />
    <axis
      xyz="0 0 -1" />
    <limit
      lower="0"
      upper="0.495"
      effort="100000"
      velocity="5" />
    <dynamics
      damping="0.1"
      friction="0.1" />
  </joint>
  <link
    name="rot_1_link">
    <inertial>
      <origin
        xyz="0.16926 -3.5483E-07 0.020067"
        rpy="0 0 0" />
      <mass
        value="1.3165" />
      <inertia
        ixx="0.00098867"
        ixy="-1.6132E-08"
        ixz="-0.00030206"
        iyy="0.015621"
        iyz="1.2571E-08"
        izz="0.01592" />
    </inertial>
    <visual>
      <origin
        xyz="0 0 0"
        rpy="0 0 0" />
      <geometry>
        <mesh
          filename="package://igus_description/meshes/rot_1_link.STL" />
      </geometry>
      <material
        name="">
        <color
          rgba="0.79216 0.81961 0.93333 1" />
      </material>
    </visual>
    <collision>
      <origin
        xyz="0 0 0"
        rpy="0 0 0" />
      <geometry>
        <mesh
          filename="package://igus_description/meshes/rot_1_link.STL" />
      </geometry>
    </collision>
  </link>
  <joint
    name="rot_1_joint"
    type="revolute">
    <origin
      xyz="0.184 0 0"
      rpy="0 0 0" />
    <parent
      link="prism_link" />
    <child
      link="rot_1_link" />
    <axis
      xyz="0 0 1" />
    <limit
      lower="-1.57"
      upper="1.57"
      effort="100000"
      velocity="5" />
    <dynamics
      damping="0.1"
      friction="0.1" />
  </joint>
  <link
    name="rot_2_link">
    <inertial>
      <origin
        xyz="0.10239 -1.6692E-17 -0.024764"
        rpy="0 0 0" />
      <mass
        value="0.66429" />
      <inertia
        ixx="0.00032966"
        ixy="-3.0928E-20"
        ixz="-8.2328E-06"
        iyy="0.0024737"
        iyz="-4.0017E-21"
        izz="0.0026703" />
    </inertial>
    <visual>
      <origin
        xyz="0 0 0"
        rpy="0 0 0" />
      <geometry>
        <mesh
          filename="package://igus_description/meshes/rot_2_link.STL" />
      </geometry>
      <material
        name="">
        <color
          rgba="0.79216 0.81961 0.93333 1" />
      </material>
    </visual>
    <collision>
      <origin
        xyz="0 0 0"
        rpy="0 0 0" />
      <geometry>
        <mesh
          filename="package://igus_description/meshes/rot_2_link.STL" />
      </geometry>
    </collision>
  </link>
  <joint
    name="rot_2_joint"
    type="revolute">
    <origin
      xyz="0.3 0 0"
      rpy="0 0 0" />
    <parent
      link="rot_1_link" />
    <child
      link="rot_2_link" />
    <axis
      xyz="0 0 1" />
    <limit
      lower="-1.57"
      upper="1.57"
      effort="100000"
      velocity="5" />
    <dynamics
      damping="0.1"
      friction="0.1" />
  </joint>
  <link
    name="tcp_link">
    <inertial>
      <origin
        xyz="-0.51654 0.00035286 0.13491"
        rpy="0 0 0" />
      <mass
        value="6.6558" />
      <inertia
        ixx="0.79615"
        ixy="0.00042314"
        ixz="0.24301"
        iyy="1.093"
        iyz="-0.00047912"
        izz="0.33517" />
    </inertial>
    <visual>
      <origin
        xyz="0 0 0"
        rpy="0 0 0" />
      <geometry>
        <mesh
          filename="package://igus_description/meshes/tcp_link.STL" />
      </geometry>
      <material
        name="">
        <color
          rgba="1 1 1 1" />
      </material>
    </visual>
    <collision>
      <origin
        xyz="0 0 0"
        rpy="0 0 0" />
      <geometry>
        <mesh
          filename="package://igus_description/meshes/tcp_link.STL" />
      </geometry>
    </collision>
  </link>
  <joint
    name="tcp_joint"
    type="fixed">
    <!-- <origin
      xyz="0.17077 0 -0.12233"
      rpy="3.1416 0 0" /> -->
      <origin
      xyz="0.17077 0 -0.12233"
      rpy="0 0 0" /> 
    <parent
      link="rot_2_link" />
    <child
      link="tcp_link" />
    <axis
      xyz="0 0 0" />
  </joint>

  <transmission name="prism_link_trans">
    <type>transmission_interface/SimpleTransmission</type>
    <joint name="prism_joint">
      <hardwareInterface>hardware_interface/PositionJointInterface</hardwareInterface>
    </joint>
    <actuator name="prism_link_motor">
      <hardwareInterface>hardware_interface/PositionJointInterface</hardwareInterface>
      <mechanicalReduction>1</mechanicalReduction>
    </actuator>
  </transmission>

  <transmission name="rot_1_link_trans">
    <type>transmission_interface/SimpleTransmission</type>
    <joint name="rot_1_joint">
      <hardwareInterface>hardware_interface/PositionJointInterface</hardwareInterface>
    </joint>
    <actuator name="rot_1_link_motor">
      <hardwareInterface>hardware_interface/PositionJointInterface</hardwareInterface>
      <mechanicalReduction>1</mechanicalReduction>
    </actuator>
  </transmission>

  <transmission name="rot_2_link_trans">
    <type>transmission_interface/SimpleTransmission</type>
    <joint name="rot_2_joint">
      <hardwareInterface>hardware_interface/PositionJointInterface</hardwareInterface>
    </joint>
    <actuator name="rot_2_link_motor">
      <hardwareInterface>hardware_interface/PositionJointInterface</hardwareInterface>
      <mechanicalReduction>1</mechanicalReduction>
    </actuator>
  </transmission>

  <!--<transmission name="tcp_link_trans">
    <type>transmission_interface/SimpleTransmission</type>
    <joint name="tcp_joint">
      <hardwareInterface>hardware_interface/PositionJointInterface</hardwareInterface>
    </joint>
    <actuator name="tcp_link_motor">
      <hardwareInterface>hardware_interface/PositionJointInterface</hardwareInterface>
      <mechanicalReduction>1</mechanicalReduction>
    </actuator>
  </transmission>-->

  <gazebo>
    <plugin name="control" filename="libgazebo_ros_control.so">
      <robotNamespace>/</robotNamespace>
    </plugin>
  </gazebo>

  <gazebo reference="prism_link">
    <selfCollide>true</selfCollide>
  </gazebo>

  <gazebo reference="rot_1_link">
    <selfCollide>true</selfCollide>
  </gazebo>

  <gazebo reference="rot_2_link">
    <selfCollide>true</selfCollide>
  </gazebo>



</robot>